<?xml version="1.0"?>
<robot name="iris_drone" xmlns:xacro="http://www.ros.org/wiki/xacro">
  
  <link name="base_link">
    <visual>
      <origin rpy="0 0 0" xyz="0 0 0"/>
      <geometry>
        <mesh filename="package://iris_description/meshes/iris.stl"/>
      </geometry>
      <material name="DarkGrey">
        <color rgba="0.2 0.2 0.2 1.0"/> 
      </material>
    </visual>
    <collision name="base_link_inertia_collision">
      <geometry>
        <box size="0.47 0.47 0.11"/>
      </geometry>
    </collision>
    <inertial>
      <mass value="1.5"/>
      <origin xyz="0 0 0" rpy="0 0 0"/>
      <inertia ixx="0.029125" ixy="0.0" ixz="0.0" iyy="0.029125" iyz="0.0" izz="0.055225"/>
    </inertial>
  </link>

  <!-- rplidar -->
  <link name="rplidar_link">
    <inertial>
      <mass value="0.19"/>
      <inertia 
        ixx="4.15e-6" 
        ixy="0" 
        ixz="0" 
        iyy="2.407e-6" 
        iyz="0" 
        izz="2.407e-6"/>
    </inertial>
    <collision name="rplidar_collision">
      <geometry>
        <cylinder length="0.005" radius="0.08"/>
      </geometry>
      <surface>
        <contact>
          <ode/>
        </contact>
        <friction>
          <ode/>
        </friction>
      </surface>
    </collision>
    <visual name="rplidar_visual">
      <geometry>
        <box>
          <size>0.02 0.05 0.05</size>
        </box>
      </geometry>
      <material name="black">
        <color rgba="0.0 0.0 0.0 1.0"/>
      </material>
    </visual>
  </link>
  
  <joint name="rplidar_joint" type="fixed">
    <parent link="base_link"/>
    <child link="rplidar_link"/>
    <origin xyz="-0.1 0.0 0.0" rpy="0 1.5708 0"/>
    <axis xyz="0 0 1"/>
    <limit lower="-1e+16" upper="1e+16" effort="1000" velocity="100"/>
    <dynamics damping="0" friction="0"/>
  </joint>
  
  <!-- Rotor 0 -->
  <link name="rotor_0">
    <inertial>
      <mass value="0.005"/>
      <inertia 
        ixx="9.75e-07" 
        ixy="0" 
        ixz="0" 
        iyy="0.000273104" 
        iyz="0" 
        izz="0.000274004"/>
    </inertial>
    <collision name="rotor_0_collision">
      <geometry>
        <cylinder length="0.005" radius="0.128"/>
      </geometry>
      <surface>
        <contact>
          <ode/>
        </contact>
        <friction>
          <ode/>
        </friction>
      </surface>
    </collision>
    <visual name="rotor_0_visual">
      <geometry>
        <mesh filename="package://iris_description/meshes/iris_prop_ccw.dae"/>
      </geometry>
      <material name="blue">
        <color rgba="0.0 0.0 1.0 1.0"/>
      </material>
    </visual>
  </link>
  
  <joint name="rotor_0_joint" type="revolute">
    <parent link="base_link"/>
    <child link="rotor_0"/>
    <origin xyz="0.13 -0.22 0.023" rpy="0 0 0"/>
    <axis xyz="0 0 1"/>
    <limit lower="-1e+16" upper="1e+16" effort="1000" velocity="100"/>
    <dynamics damping="0" friction="0"/>
  </joint>

  <!-- Rotor 1 -->
  <link name="rotor_1">
    <inertial>
      <mass value="0.005"/>
      <inertia 
        ixx="9.75e-07" 
        ixy="0" 
        ixz="0" 
        iyy="0.000273104" 
        iyz="0" 
        izz="0.000274004"/>
    </inertial>
    <collision name="rotor_1_collision">
      <geometry>
        <cylinder length="0.005" radius="0.128"/>
      </geometry>
      <surface>
        <contact>
          <ode/>
        </contact>
        <friction>
          <ode/>
        </friction>
      </surface>
    </collision>
    <visual name="rotor_1_visual">
      <geometry>
        <mesh filename="package://iris_description/meshes/iris_prop_ccw.dae"/>
      </geometry>
      <material name="blue">
        <color rgba="0.0 0.0 1.0 1.0"/>
      </material>
    </visual>
  </link>

  <joint name="rotor_1_joint" type="revolute">
    <parent link="base_link"/>
    <child link="rotor_1"/>
    <origin xyz="-0.13 0.22 0.023" rpy="0 0 0"/>
    <axis xyz="0 0 1"/>
    <limit lower="-1e+16" upper="1e+16" effort="1000" velocity="100"/>
    <dynamics damping="0" friction="0"/>
  </joint>

  <!-- Rotor 2 -->
  <link name="rotor_2">
    <inertial>
      <mass value="0.005"/>
      <inertia 
        ixx="9.75e-07" 
        ixy="0" 
        ixz="0" 
        iyy="0.000273104" 
        iyz="0" 
        izz="0.000274004"/>
    </inertial>
    <collision name="rotor_2_collision">
      <geometry>
        <cylinder length="0.005" radius="0.128"/>
      </geometry>
      <surface>
        <contact>
          <ode/>
        </contact>
        <friction>
          <ode/>
        </friction>
      </surface>
    </collision>
    <visual name="rotor_2_visual">
      <geometry>
        <mesh filename="package://iris_description/meshes/iris_prop_cw.dae"/>
      </geometry>
      <material name="blue">
        <color rgba="0.0 0.0 1.0 1.0"/>
      </material>
    </visual>
  </link>

  <joint name="rotor_2_joint" type="revolute">
    <parent link="base_link"/>
    <child link="rotor_2"/>
    <origin xyz="0.13 0.22 0.023" rpy="0 0 0"/>
    <axis xyz="0 0 1"/>
    <limit lower="-1e+16" upper="1e+16" effort="1000" velocity="100"/>
    <dynamics damping="0" friction="0"/>
  </joint>

  <!-- Rotor 3 -->
  <link name="rotor_3">
    <inertial>
      <mass value="0.005"/>
      <inertia 
        ixx="9.75e-07" 
        ixy="0" 
        ixz="0" 
        iyy="0.000273104" 
        iyz="0" 
        izz="0.000274004"/>
    </inertial>
    <collision name="rotor_3_collision">
      <geometry>
        <cylinder length="0.005" radius="0.128"/>
      </geometry>
      <surface>
        <contact>
          <ode/>
        </contact>
        <friction>
          <ode/>
        </friction>
      </surface>
    </collision>
    <visual name="rotor_3_visual">
      <geometry>
        <mesh filename="package://iris_description/meshes/iris_prop_cw.dae"/>
      </geometry>
      <material name="blue">
        <color rgba="0.0 0.0 1.0 1.0"/>
      </material>
    </visual>
  </link>

  <joint name="rotor_3_joint" type="revolute">
    <parent link="base_link"/>
    <child link="rotor_3"/>
    <origin xyz="-0.13 -0.22 0.023" rpy="0 0 0"/>
    <axis xyz="0 0 1"/>
    <limit lower="-1e+16" upper="1e+16" effort="1000" velocity="100"/>
    <dynamics damping="0" friction="0"/>
  </joint>

</robot>
